Workbook

Sheet Dashboard
A1: FY2011 Revenue Variance — Plan vs Actual (by product category)
A2: Finding: revenue came in ~9% below a +10% growth plan, driven by a volume shortfall (-£1.42M). Pricing (+£0.35M) and mix (+£0.18M) partly offset it. Unlike the by-market view, product mix is now a real story: customers shifted toward Storage and Home & Decor and away from Kitchen & Dining and the long tail. Like-for-like Jan–Nov.
J3: Helper tables (drive the charts)
A4: Budget revenue | C4: Actual revenue | E4: Total variance | G4: Variance % | J4: Step | K4: Value | L4: CumEnd | M4: Base | N4: Decrease | O4: Increase | P4: Total
A5: =Model!F25 -> 9787586.6 | C5: =Model!C37 -> 8887999.8 | E5: =Model!C37-Model!F25 -> -899586.79 | G5: =(Model!C37-Model!F25)/Model!F25 -> -0.091910991 | J5: Budget | K5: =Model!B40 -> 9787586.6 | L5: =K5 -> 9787586.6 | M5: 0 | N5: 0 | O5: 0 | P5: =K5 -> 9787586.6
J6: Volume | K6: =Model!B41 -> -1424111.6 | L6: =L5+K6 -> 8363475 | M6: =L6-MAX(K6,0) -> 8363475 | N6: =MAX(-K6,0) -> 1424111.6 | O6: =MAX(K6,0) -> 0 | P6: 0
J7: Mix | K7: =Model!B42 -> 177313.96 | L7: =L6+K7 -> 8540789 | M7: =L7-MAX(K7,0) -> 8363475 | N7: =MAX(-K7,0) -> 0 | O7: =MAX(K7,0) -> 177313.96 | P7: 0
J8: Price | K8: =Model!B43 -> 347210.84 | L8: =L7+K8 -> 8887999.8 | M8: =L8-MAX(K8,0) -> 8540789 | N8: =MAX(-K8,0) -> 0 | O8: =MAX(K8,0) -> 347210.84 | P8: 0
J9: Actual | K9: =Model!B44 -> 8887999.8 | L9: =K9 -> 8887999.8 | M9: 0 | N9: 0 | O9: 0 | P9: =K9 -> 8887999.8
J12: Month | K12: Budget | L12: Actual
J13: 1 | K13: =SUMIFS(Data!$E:$E,Data!$A:$A,Assumptions!$B$3,Data!$B:$B,J13)*(Model!$F$25/Model!$C$13) -> 705676.29 | L13: =SUMIFS(Data!$E:$E,Data!$A:$A,Assumptions!$B$4,Data!$B:$B,J13) -> 671933.19
J14: 2 | K14: =SUMIFS(Data!$E:$E,Data!$A:$A,Assumptions!$B$3,Data!$B:$B,J14)*(Model!$F$25/Model!$C$13) -> 611547.73 | L14: =SUMIFS(Data!$E:$E,Data!$A:$A,Assumptions!$B$4,Data!$B:$B,J14) -> 508886.2
J15: 3 | K15: =SUMIFS(Data!$E:$E,Data!$A:$A,Assumptions!$B$3,Data!$B:$B,J15)*(Model!$F$25/Model!$C$13) -> 865990.25 | L15: =SUMIFS(Data!$E:$E,Data!$A:$A,Assumptions!$B$4,Data!$B:$B,J15) -> 691257.61
J16: 4 | K16: =SUMIFS(Data!$E:$E,Data!$A:$A,Assumptions!$B$3,Data!$B:$B,J16)*(Model!$F$25/Model!$C$13) -> 735484.4 | L16: =SUMIFS(Data!$E:$E,Data!$A:$A,Assumptions!$B$4,Data!$B:$B,J16) -> 516248.12
J17: 5 | K17: =SUMIFS(Data!$E:$E,Data!$A:$A,Assumptions!$B$3,Data!$B:$B,J17)*(Model!$F$25/Model!$C$13) -> 731631.78 | L17: =SUMIFS(Data!$E:$E,Data!$A:$A,Assumptions!$B$4,Data!$B:$B,J17) -> 741177.41
J18: 6 | K18: =SUMIFS(Data!$E:$E,Data!$A:$A,Assumptions!$B$3,Data!$B:$B,J18)*(Model!$F$25/Model!$C$13) -> 793153.33 | L18: =SUMIFS(Data!$E:$E,Data!$A:$A,Assumptions!$B$4,Data!$B:$B,J18) -> 738601.87
J19: 7 | K19: =SUMIFS(Data!$E:$E,Data!$A:$A,Assumptions!$B$3,Data!$B:$B,J19)*(Model!$F$25/Model!$C$13) -> 719338.29 | L19: =SUMIFS(Data!$E:$E,Data!$A:$A,Assumptions!$B$4,Data!$B:$B,J19) -> 689199.41
J20: 8 | K20: =SUMIFS(Data!$E:$E,Data!$A:$A,Assumptions!$B$3,Data!$B:$B,J20)*(Model!$F$25/Model!$C$13) -> 766194.33 | L20: =SUMIFS(Data!$E:$E,Data!$A:$A,Assumptions!$B$4,Data!$B:$B,J20) -> 736357.23
J21: 9 | K21: =SUMIFS(Data!$E:$E,Data!$A:$A,Assumptions!$B$3,Data!$B:$B,J21)*(Model!$F$25/Model!$C$13) -> 987838.16 | L21: =SUMIFS(Data!$E:$E,Data!$A:$A,Assumptions!$B$4,Data!$B:$B,J21) -> 1030385.4
J22: 10 | K22: =SUMIFS(Data!$E:$E,Data!$A:$A,Assumptions!$B$3,Data!$B:$B,J22)*(Model!$F$25/Model!$C$13) -> 1244054 | L22: =SUMIFS(Data!$E:$E,Data!$A:$A,Assumptions!$B$4,Data!$B:$B,J22) -> 1106582.9
J23: 11 | K23: =SUMIFS(Data!$E:$E,Data!$A:$A,Assumptions!$B$3,Data!$B:$B,J23)*(Model!$F$25/Model!$C$13) -> 1626678 | L23: =SUMIFS(Data!$E:$E,Data!$A:$A,Assumptions!$B$4,Data!$B:$B,J23) -> 1457370.5

Sheet Model
A1: Calculation engine — Base → Budget → Actual → Price/Volume/Mix bridge
A2: All figures are Jan–Nov (like-for-like). Segment = market.
A3: 1. Base year actuals (Jan–Nov, = Assumptions base year)
A4: Market | B4: Units | C4: Revenue | D4: Avg Price
A5: Home & Decor | B5: =SUMIFS(Data!$D:$D,Data!$A:$A,Assumptions!$B$3,Data!$C:$C,$A5,Data!$B:$B,"<="&Assumptions!$B$5) -> 736408 | C5: =SUMIFS(Data!$E:$E,Data!$A:$A,Assumptions!$B$3,Data!$C:$C,$A5,Data!$B:$B,"<="&Assumptions!$B$5) -> 1416697.6 | D5: =C5/B5 -> 1.9237944
A6: Kitchen & Dining | B6: =SUMIFS(Data!$D:$D,Data!$A:$A,Assumptions!$B$3,Data!$C:$C,$A6,Data!$B:$B,"<="&Assumptions!$B$5) -> 864370 | C6: =SUMIFS(Data!$E:$E,Data!$A:$A,Assumptions!$B$3,Data!$C:$C,$A6,Data!$B:$B,"<="&Assumptions!$B$5) -> 1334531.3 | D6: =C6/B6 -> 1.5439353
A7: Storage | B7: =SUMIFS(Data!$D:$D,Data!$A:$A,Assumptions!$B$3,Data!$C:$C,$A7,Data!$B:$B,"<="&Assumptions!$B$5) -> 387574 | C7: =SUMIFS(Data!$E:$E,Data!$A:$A,Assumptions!$B$3,Data!$C:$C,$A7,Data!$B:$B,"<="&Assumptions!$B$5) -> 917799.12 | D7: =C7/B7 -> 2.3680616
A8: Bags | B8: =SUMIFS(Data!$D:$D,Data!$A:$A,Assumptions!$B$3,Data!$C:$C,$A8,Data!$B:$B,"<="&Assumptions!$B$5) -> 456394 | C8: =SUMIFS(Data!$E:$E,Data!$A:$A,Assumptions!$B$3,Data!$C:$C,$A8,Data!$B:$B,"<="&Assumptions!$B$5) -> 753821.83 | D8: =C8/B8 -> 1.6516909
A9: Lighting | B9: =SUMIFS(Data!$D:$D,Data!$A:$A,Assumptions!$B$3,Data!$C:$C,$A9,Data!$B:$B,"<="&Assumptions!$B$5) -> 446785 | C9: =SUMIFS(Data!$E:$E,Data!$A:$A,Assumptions!$B$3,Data!$C:$C,$A9,Data!$B:$B,"<="&Assumptions!$B$5) -> 732027.9 | D9: =C9/B9 -> 1.6384344
A10: Party & Seasonal | B10: =SUMIFS(Data!$D:$D,Data!$A:$A,Assumptions!$B$3,Data!$C:$C,$A10,Data!$B:$B,"<="&Assumptions!$B$5) -> 362235 | C10: =SUMIFS(Data!$E:$E,Data!$A:$A,Assumptions!$B$3,Data!$C:$C,$A10,Data!$B:$B,"<="&Assumptions!$B$5) -> 674230.7 | D10: =C10/B10 -> 1.8613074
A11: Stationery & Craft | B11: =SUMIFS(Data!$D:$D,Data!$A:$A,Assumptions!$B$3,Data!$C:$C,$A11,Data!$B:$B,"<="&Assumptions!$B$5) -> 547278 | C11: =SUMIFS(Data!$E:$E,Data!$A:$A,Assumptions!$B$3,Data!$C:$C,$A11,Data!$B:$B,"<="&Assumptions!$B$5) -> 628915.98 | D11: =C11/B11 -> 1.149171
A12: Other | B12: =SUMIFS(Data!$D:$D,Data!$A:$A,Assumptions!$B$3,Data!$C:$C,$A12,Data!$B:$B,"<="&Assumptions!$B$5) -> 1417334 | C12: =SUMIFS(Data!$E:$E,Data!$A:$A,Assumptions!$B$3,Data!$C:$C,$A12,Data!$B:$B,"<="&Assumptions!$B$5) -> 2180622.1 | D12: =C12/B12 -> 1.5385379
A13: Total | B13: =SUM(B5:B12) -> 5218378 | C13: =SUM(C5:C12) -> 8638646.6 | D13: =C13/B13 -> 1.6554275
A15: 2. Budget (base × plan assumptions)
A16: Market | B16: Vol Gr % | C16: Price Ch % | D16: Bud Units | E16: Bud Price | F16: Bud Revenue
A17: =A5 -> Home & Decor | B17: =Assumptions!B9 -> 0.1 | C17: =Assumptions!C9 -> 0.03 | D17: =B5*(1+B17) -> 810048.8 | E17: =D5*(1+C17) -> 1.9815082 | F17: =D17*E17 -> 1605118.4
A18: =A6 -> Kitchen & Dining | B18: =Assumptions!B10 -> 0.1 | C18: =Assumptions!C10 -> 0.03 | D18: =B6*(1+B18) -> 950807 | E18: =D6*(1+C18) -> 1.5902533 | F18: =D18*E18 -> 1512024
A19: =A7 -> Storage | B19: =Assumptions!B11 -> 0.1 | C19: =Assumptions!C11 -> 0.03 | D19: =B7*(1+B19) -> 426331.4 | E19: =D7*(1+C19) -> 2.4391035 | F19: =D19*E19 -> 1039866.4
A20: =A8 -> Bags | B20: =Assumptions!B12 -> 0.1 | C20: =Assumptions!C12 -> 0.03 | D20: =B8*(1+B20) -> 502033.4 | E20: =D8*(1+C20) -> 1.7012417 | F20: =D20*E20 -> 854080.13
A21: =A9 -> Lighting | B21: =Assumptions!B13 -> 0.1 | C21: =Assumptions!C13 -> 0.03 | D21: =B9*(1+B21) -> 491463.5 | E21: =D9*(1+C21) -> 1.6875874 | F21: =D21*E21 -> 829387.61
A22: =A10 -> Party & Seasonal | B22: =Assumptions!B14 -> 0.1 | C22: =Assumptions!C14 -> 0.03 | D22: =B10*(1+B22) -> 398458.5 | E22: =D10*(1+C22) -> 1.9171467 | F22: =D22*E22 -> 763903.38
A23: =A11 -> Stationery & Craft | B23: =Assumptions!B15 -> 0.1 | C23: =Assumptions!C15 -> 0.03 | D23: =B11*(1+B23) -> 602005.8 | E23: =D11*(1+C23) -> 1.1836461 | F23: =D23*E23 -> 712561.81
A24: =A12 -> Other | B24: =Assumptions!B16 -> 0.1 | C24: =Assumptions!C16 -> 0.03 | D24: =B12*(1+B24) -> 1559067.4 | E24: =D12*(1+C24) -> 1.5846941 | F24: =D24*E24 -> 2470644.9
A25: Total | D25: =SUM(D17:D24) -> 5740215.8 | F25: =SUM(F17:F24) -> 9787586.6
A27: 3. Actual (Jan–Nov, = Assumptions budget year) + per-segment effects
A28: Market | B28: Act Units | C28: Act Revenue | D28: Act Price | E28: Mix effect | F28: Price effect
A29: =A5 -> Home & Decor | B29: =SUMIFS(Data!$D:$D,Data!$A:$A,Assumptions!$B$4,Data!$C:$C,$A29,Data!$B:$B,"<="&Assumptions!$B$5) -> 775719 | C29: =SUMIFS(Data!$E:$E,Data!$A:$A,Assumptions!$B$4,Data!$C:$C,$A29,Data!$B:$B,"<="&Assumptions!$B$5) -> 1672112.6 | D29: =C29/B29 -> 2.1555648 | E29: =(B29-D17*($B$37/$D$25))*E17 -> 165522.85 | F29: =(D29-E17)*B29 -> 135018.99
A30: =A6 -> Kitchen & Dining | B30: =SUMIFS(Data!$D:$D,Data!$A:$A,Assumptions!$B$4,Data!$C:$C,$A30,Data!$B:$B,"<="&Assumptions!$B$5) -> 682409 | C30: =SUMIFS(Data!$E:$E,Data!$A:$A,Assumptions!$B$4,Data!$C:$C,$A30,Data!$B:$B,"<="&Assumptions!$B$5) -> 1347498 | D30: =C30/B30 -> 1.9746193 | E30: =(B30-D18*($B$37/$D$25))*E18 -> -206818.58 | F30: =(D30-E18)*B30 -> 262294.8
A31: =A7 -> Storage | B31: =SUMIFS(Data!$D:$D,Data!$A:$A,Assumptions!$B$4,Data!$C:$C,$A31,Data!$B:$B,"<="&Assumptions!$B$5) -> 510279 | C31: =SUMIFS(Data!$E:$E,Data!$A:$A,Assumptions!$B$4,Data!$C:$C,$A31,Data!$B:$B,"<="&Assumptions!$B$5) -> 1112428.5 | D31: =C31/B31 -> 2.1800398 | E31: =(B31-D19*($B$37/$D$25))*E19 -> 356059.33 | F31: =(D31-E19)*B31 -> -132194.75
A32: =A8 -> Bags | B32: =SUMIFS(Data!$D:$D,Data!$A:$A,Assumptions!$B$4,Data!$C:$C,$A32,Data!$B:$B,"<="&Assumptions!$B$5) -> 526413 | C32: =SUMIFS(Data!$E:$E,Data!$A:$A,Assumptions!$B$4,Data!$C:$C,$A32,Data!$B:$B,"<="&Assumptions!$B$5) -> 950584.14 | D32: =C32/B32 -> 1.8057763 | E32: =(B32-D20*($B$37/$D$25))*E20 -> 165745.8 | F32: =(D32-E20)*B32 -> 55028.416
A33: =A9 -> Lighting | B33: =SUMIFS(Data!$D:$D,Data!$A:$A,Assumptions!$B$4,Data!$C:$C,$A33,Data!$B:$B,"<="&Assumptions!$B$5) -> 372330 | C33: =SUMIFS(Data!$E:$E,Data!$A:$A,Assumptions!$B$4,Data!$C:$C,$A33,Data!$B:$B,"<="&Assumptions!$B$5) -> 670165.31 | D33: =C33/B33 -> 1.7999229 | E33: =(B33-D21*($B$37/$D$25))*E21 -> -80370.793 | F33: =(D33-E21)*B33 -> 41825.893
A34: =A10 -> Party & Seasonal | B34: =SUMIFS(Data!$D:$D,Data!$A:$A,Assumptions!$B$4,Data!$C:$C,$A34,Data!$B:$B,"<="&Assumptions!$B$5) -> 391497 | C34: =SUMIFS(Data!$E:$E,Data!$A:$A,Assumptions!$B$4,Data!$C:$C,$A34,Data!$B:$B,"<="&Assumptions!$B$5) -> 760151.32 | D34: =C34/B34 -> 1.941653 | E34: =(B34-D22*($B$37/$D$25))*E22 -> 97803.11 | F34: =(D34-E22)*B34 -> 9594.1534
A35: =A11 -> Stationery & Craft | B35: =SUMIFS(Data!$D:$D,Data!$A:$A,Assumptions!$B$4,Data!$C:$C,$A35,Data!$B:$B,"<="&Assumptions!$B$5) -> 522520 | C35: =SUMIFS(Data!$E:$E,Data!$A:$A,Assumptions!$B$4,Data!$C:$C,$A35,Data!$B:$B,"<="&Assumptions!$B$5) -> 565313.7 | D35: =C35/B35 -> 1.0818987 | E35: =(B35-D23*($B$37/$D$25))*E23 -> 9595.9782 | F35: =(D35-E23)*B35 -> -53165.05
A36: =A12 -> Other | B36: =SUMIFS(Data!$D:$D,Data!$A:$A,Assumptions!$B$4,Data!$C:$C,$A36,Data!$B:$B,"<="&Assumptions!$B$5) -> 1123837 | C36: =SUMIFS(Data!$E:$E,Data!$A:$A,Assumptions!$B$4,Data!$C:$C,$A36,Data!$B:$B,"<="&Assumptions!$B$5) -> 1809746.2 | D36: =C36/B36 -> 1.610328 | E36: =(B36-D24*($B$37/$D$25))*E24 -> -330223.73 | F36: =(D36-E24)*B36 -> 28808.385
A37: Total | B37: =SUM(B29:B36) -> 4905004 | C37: =SUM(C29:C36) -> 8887999.8 | E37: =SUM(E29:E36) -> 177313.96 | F37: =SUM(F29:F36) -> 347210.84
A39: 4. Revenue bridge: Budget → Volume → Mix → Price → Actual
A40: Budget revenue | B40: =F25 -> 9787586.6
A41: Volume effect | B41: =(B37-D25)*(F25/D25) -> -1424111.6
A42: Mix effect | B42: =E37 -> 177313.96
A43: Price effect | B43: =F37 -> 347210.84
...

Sheet Assumptions
A1: FP&A Variance Model — Assumptions (the plan, set in advance)
A3: Base year (actuals the plan is built from) | B3: 2010
A4: Budget year (plan vs actual compared) | B4: 2011
A5: Through month (period cutoff) | B5: 11 | C5: Set to 11: December 2011 is truncated in the source, so compare like-for-like (Jan-Nov).
A6: Blue / shaded cells are inputs. Change them and the whole model + bridge update.
A7: Comparison is like-for-like Jan–Nov (December 2011 is truncated in the source, so it is excluded).
A8: Market segment | B8: Volume Growth % | C8: Price Change %
A9: Home & Decor | B9: 0.1 | C9: 0.03
A10: Kitchen & Dining | B10: 0.1 | C10: 0.03
A11: Storage | B11: 0.1 | C11: 0.03
A12: Bags | B12: 0.1 | C12: 0.03
A13: Lighting | B13: 0.1 | C13: 0.03
A14: Party & Seasonal | B14: 0.1 | C14: 0.03
A15: Stationery & Craft | B15: 0.1 | C15: 0.03
A16: Other | B16: 0.1 | C16: 0.03

Sheet Data
A1: MONTHLY FACT TABLE — output of sql/build_fact_table_by_category.sql (DuckDB)
A2: Imported from the data pipeline (real Online Retail II). Re-run the SQL to refresh; do not edit by hand.
A4: year | B4: month | C4: category | D4: units | E4: revenue | F4: avg_price
A5: 2009 | B5: 12 | C5: Bags | D5: 33988 | E5: 47869.25 | F5: 1.4084
A6: 2009 | B6: 12 | C6: Home & Decor | D6: 67453 | E6: 112837.15 | F6: 1.6728
A7: 2009 | B7: 12 | C7: Kitchen & Dining | D7: 59147 | E7: 149098.59 | F7: 2.5208
A8: 2009 | B8: 12 | C8: Lighting | D8: 53210 | E8: 109538.12 | F8: 2.0586
A9: 2009 | B9: 12 | C9: Other | D9: 132002 | E9: 227869.43 | F9: 1.7263
A10: 2009 | B10: 12 | C10: Party & Seasonal | D10: 22676 | E10: 39157.86 | F10: 1.7268
A11: 2009 | B11: 12 | C11: Stationery & Craft | D11: 30157 | E11: 38605.1 | F11: 1.2801
A12: 2009 | B12: 12 | C12: Storage | D12: 28132 | E12: 76255.97 | F12: 2.7106
A13: 2010 | B13: 1 | C13: Bags | D13: 31718 | E13: 52465.94 | F13: 1.6541
A14: 2010 | B14: 1 | C14: Home & Decor | D14: 74318 | E14: 101988.95 | F14: 1.3723
A15: 2010 | B15: 1 | C15: Kitchen & Dining | D15: 57157 | E15: 97090.77 | F15: 1.6987
A16: 2010 | B16: 1 | C16: Lighting | D16: 39088 | E16: 69786.57 | F16: 1.7854
... A204: 2011 | B204: 12 | C204: Storage | D204: 18227 | E204: 45013.24 | F204: 2.4696

Sheet Notes
A1: Methodology & Notes
A3: DATA SOURCE
A4: • UCI 'Online Retail II' — real UK online-retail transactions, Dec 2009 – Dec 2011 (~1.07M rows).
A5: • Pipeline: sql/build_fact_table_by_category.sql (DuckDB).
A7: CLEANING (Stage 2 profiling on 1,067,371 raw rows)
A8: • Dropped cancellations ('C' invoices), non-positive quantities, and non-positive prices (~2.4%).
A9: • Kept 1,041,670 rows (97.6%). Missing Customer IDs (243,007) retained — revenue does not need them.
A11: SEGMENTATION (v2 'by product category' cut)
A12: • Segment = product category derived from item descriptions via keyword rules in the SQL.
A13: • Eight categories: Home & Decor, Kitchen & Dining, Storage, Bags, Lighting, Party & Seasonal, Stationery & Craft, Other.
A14: • Non-product lines (postage, carriage, manual adjustments, gift vouchers, ~GBP 0.84M) are excluded.
A15: • 'Other' is ~23% of revenue (genuine long-tail miscellany); categories are balanced, so mix is a real driver here.
... A33: • Change the Assumptions and the variance — and the story — change accordingly.
